The following modules were not unloaded:
  (Use "module --force purge" to unload all):

  1) nvidia/.latest   2) slurm/.latest
/fred/oz413/.conda/envs/llm-env/lib/python3.10/site-packages/transformers/utils/generic.py:311: FutureWarning: `torch.utils._pytree._register_pytree_node` is deprecated. Please use `torch.utils._pytree.register_pytree_node` instead.
  torch.utils._pytree._register_pytree_node(
The following values were not passed to `accelerate launch` and had defaults used instead:
	`--num_processes` was set to a value of `1`
	`--num_machines` was set to a value of `1`
	`--mixed_precision` was set to a value of `'no'`
	`--dynamo_backend` was set to a value of `'no'`
To avoid this warning pass in values for each of the problematic parameters or run `accelerate config`.
/fred/oz413/.conda/envs/llm-env/lib/python3.10/site-packages/transformers/utils/generic.py:311: FutureWarning: `torch.utils._pytree._register_pytree_node` is deprecated. Please use `torch.utils._pytree.register_pytree_node` instead.
  torch.utils._pytree._register_pytree_node(
'(MaxRetryError("HTTPSConnectionPool(host='huggingface.co', port=443): Max retries exceeded with url: /gpt2-xl/resolve/main/config.json (Caused by ProxyError('Unable to connect to proxy', NewConnectionError('<urllib3.connection.HTTPSConnection object at 0x1492eee56350>: Failed to establish a new connection: [Errno 113] No route to host')))"), '(Request ID: c2b60437-2390-42e9-8a10-acdaf63c28ba)')' thrown while requesting HEAD https://huggingface.co/gpt2-xl/resolve/main/config.json
Traceback (most recent call last):
  File "/fred/oz413/.conda/envs/llm-env/lib/python3.10/site-packages/urllib3/connection.py", line 198, in _new_conn
    sock = connection.create_connection(
  File "/fred/oz413/.conda/envs/llm-env/lib/python3.10/site-packages/urllib3/util/connection.py", line 85, in create_connection
    raise err
  File "/fred/oz413/.conda/envs/llm-env/lib/python3.10/site-packages/urllib3/util/connection.py", line 73, in create_connection
    sock.connect(sa)
OSError: [Errno 113] No route to host

The above exception was the direct cause of the following exception:

Traceback (most recent call last):
  File "/fred/oz413/.conda/envs/llm-env/lib/python3.10/site-packages/urllib3/connectionpool.py", line 773, in urlopen
    self._prepare_proxy(conn)
  File "/fred/oz413/.conda/envs/llm-env/lib/python3.10/site-packages/urllib3/connectionpool.py", line 1042, in _prepare_proxy
    conn.connect()
  File "/fred/oz413/.conda/envs/llm-env/lib/python3.10/site-packages/urllib3/connection.py", line 704, in connect
    self.sock = sock = self._new_conn()
  File "/fred/oz413/.conda/envs/llm-env/lib/python3.10/site-packages/urllib3/connection.py", line 213, in _new_conn
    raise NewConnectionError(
urllib3.exceptions.NewConnectionError: <urllib3.connection.HTTPSConnection object at 0x1492eee56350>: Failed to establish a new connection: [Errno 113] No route to host

The above exception was the direct cause of the following exception:

urllib3.exceptions.ProxyError: ('Unable to connect to proxy', NewConnectionError('<urllib3.connection.HTTPSConnection object at 0x1492eee56350>: Failed to establish a new connection: [Errno 113] No route to host'))

The above exception was the direct cause of the following exception:

Traceback (most recent call last):
  File "/fred/oz413/.conda/envs/llm-env/lib/python3.10/site-packages/requests/adapters.py", line 667, in send
    resp = conn.urlopen(
  File "/fred/oz413/.conda/envs/llm-env/lib/python3.10/site-packages/urllib3/connectionpool.py", line 841, in urlopen
    retries = retries.increment(
  File "/fred/oz413/.conda/envs/llm-env/lib/python3.10/site-packages/urllib3/util/retry.py", line 519, in increment
    raise MaxRetryError(_pool, url, reason) from reason  # type: ignore[arg-type]
urllib3.exceptions.MaxRetryError: HTTPSConnectionPool(host='huggingface.co', port=443): Max retries exceeded with url: /gpt2-xl/resolve/main/config.json (Caused by ProxyError('Unable to connect to proxy', NewConnectionError('<urllib3.connection.HTTPSConnection object at 0x1492eee56350>: Failed to establish a new connection: [Errno 113] No route to host')))

During handling of the above exception, another exception occurred:

Traceback (most recent call last):
  File "/fred/oz413/ANeurIPS2024_SPV-MIA/./ft_llms/llms_finetune.py", line 91, in <module>
    config = AutoConfig.from_pretrained(args.model_name, cache_dir=args.cache_path)
  File "/fred/oz413/.conda/envs/llm-env/lib/python3.10/site-packages/transformers/models/auto/configuration_auto.py", line 1034, in from_pretrained
    config_dict, unused_kwargs = PretrainedConfig.get_config_dict(pretrained_model_name_or_path, **kwargs)
  File "/fred/oz413/.conda/envs/llm-env/lib/python3.10/site-packages/transformers/configuration_utils.py", line 620, in get_config_dict
    config_dict, kwargs = cls._get_config_dict(pretrained_model_name_or_path, **kwargs)
  File "/fred/oz413/.conda/envs/llm-env/lib/python3.10/site-packages/transformers/configuration_utils.py", line 675, in _get_config_dict
    resolved_config_file = cached_file(
  File "/fred/oz413/.conda/envs/llm-env/lib/python3.10/site-packages/transformers/utils/hub.py", line 429, in cached_file
    resolved_file = hf_hub_download(
  File "/fred/oz413/.conda/envs/llm-env/lib/python3.10/site-packages/huggingface_hub/utils/_validators.py", line 118, in _inner_fn
    return fn(*args, **kwargs)
  File "/fred/oz413/.conda/envs/llm-env/lib/python3.10/site-packages/huggingface_hub/file_download.py", line 1195, in hf_hub_download
    metadata = get_hf_file_metadata(
  File "/fred/oz413/.conda/envs/llm-env/lib/python3.10/site-packages/huggingface_hub/utils/_validators.py", line 118, in _inner_fn
    return fn(*args, **kwargs)
  File "/fred/oz413/.conda/envs/llm-env/lib/python3.10/site-packages/huggingface_hub/file_download.py", line 1532, in get_hf_file_metadata
    r = _request_wrapper(
  File "/fred/oz413/.conda/envs/llm-env/lib/python3.10/site-packages/huggingface_hub/file_download.py", line 407, in _request_wrapper
    response = _request_wrapper(
  File "/fred/oz413/.conda/envs/llm-env/lib/python3.10/site-packages/huggingface_hub/file_download.py", line 442, in _request_wrapper
    return http_backoff(
  File "/fred/oz413/.conda/envs/llm-env/lib/python3.10/site-packages/huggingface_hub/utils/_http.py", line 274, in http_backoff
    raise err
  File "/fred/oz413/.conda/envs/llm-env/lib/python3.10/site-packages/huggingface_hub/utils/_http.py", line 258, in http_backoff
    response = session.request(method=method, url=url, **kwargs)
  File "/fred/oz413/.conda/envs/llm-env/lib/python3.10/site-packages/requests/sessions.py", line 589, in request
    resp = self.send(prep, **send_kwargs)
  File "/fred/oz413/.conda/envs/llm-env/lib/python3.10/site-packages/requests/sessions.py", line 703, in send
    r = adapter.send(request, **kwargs)
  File "/fred/oz413/.conda/envs/llm-env/lib/python3.10/site-packages/huggingface_hub/utils/_http.py", line 63, in send
    return super().send(request, *args, **kwargs)
  File "/fred/oz413/.conda/envs/llm-env/lib/python3.10/site-packages/requests/adapters.py", line 694, in send
    raise ProxyError(e, request=request)
requests.exceptions.ProxyError: (MaxRetryError("HTTPSConnectionPool(host='huggingface.co', port=443): Max retries exceeded with url: /gpt2-xl/resolve/main/config.json (Caused by ProxyError('Unable to connect to proxy', NewConnectionError('<urllib3.connection.HTTPSConnection object at 0x1492eee56350>: Failed to establish a new connection: [Errno 113] No route to host')))"), '(Request ID: c2b60437-2390-42e9-8a10-acdaf63c28ba)')
Traceback (most recent call last):
  File "/fred/oz413/.conda/envs/llm-env/bin/accelerate", line 8, in <module>
    sys.exit(main())
  File "/fred/oz413/.conda/envs/llm-env/lib/python3.10/site-packages/accelerate/commands/accelerate_cli.py", line 47, in main
    args.func(args)
  File "/fred/oz413/.conda/envs/llm-env/lib/python3.10/site-packages/accelerate/commands/launch.py", line 986, in launch_command
    simple_launcher(args)
  File "/fred/oz413/.conda/envs/llm-env/lib/python3.10/site-packages/accelerate/commands/launch.py", line 628, in simple_launcher
    raise subprocess.CalledProcessError(returncode=process.returncode, cmd=cmd)
subprocess.CalledProcessError: Command '['/fred/oz413/.conda/envs/llm-env/bin/python', './ft_llms/llms_finetune.py', '--output_dir', './ft_llms/gpt2-xl/ag_news/baseline/', '--block_size', '128', '--eval_steps', '100', '--save_epochs', '100', '--log_steps', '100', '-d', 'ag_news', '-m', 'gpt2-xl', '--packing', '--use_dataset_cache', '-e', '2', '-b', '4', '-lr', '5e-5', '--gradient_accumulation_steps', '1', '--train_sta_idx=0', '--train_end_idx=10000', '--eval_sta_idx=0', '--eval_end_idx=1000', '--dataset_config_name', 'default']' returned non-zero exit status 1.
